Workbook

Sheet 요약
A1: 공공건축 동종업계 현황 종합
A2: 작성일 2026-10-08 · 원자료 4건(엑셀 1, PDF 3) 통합 정리본 · 모든 수치는 인원명부 시트 수식 집계
B5: 기준연도 (연나이 계산) | C5: 2026 | D5: 입력값. 변경 시 전 시트 연나이 자동 재계산.
B7: 총 등재 인원(명) | C7: =COUNTA(인원명부!$H$5:$H$105) -> 101 | D7: 현황 PDF 100건 + 학교별 분석 PDF 단독 1명(이상범)
B8: 건설사 수(개사) | C8: =SUMPRODUCT(1/COUNTIF(인원명부!$F$5:$F$105,인원명부!$F$5:$F$105)) -> 31 | D8: 업체명 표준화 기준
B9: 출신학교 수(개교) | C9: =SUMPRODUCT((인원명부!$L$5:$L$105<>"")/COUNTIF(인원명부!$L$5:$L$105,인원명부!$L$5:$L$105&"")) -> 45 | D9: 대표학교 기준, 학교 미확인 1명 제외
B10: 최고 년생 | C10: =MIN(인원명부!$B$5:$B$105) -> 66
B11: 최저 년생 | C11: =MAX(인원명부!$B$5:$B$105) -> 85
B12: 임원 인원(명) | C12: =COUNTIF(인원명부!$J$5:$J$105,"임원") -> 33 | D12: 부사장·전무·상무·이사·실장 (학교별 분석 PDF 기준)
B13: 부장 이하 인원(명) | C13: =COUNTIF(인원명부!$J$5:$J$105,"부장 이하") -> 66 | D13: 부장·차장·과장·수석·책임
B14: 직급 미기재(명) | C14: =COUNTIF(인원명부!$J$5:$J$105,"미기재") -> 2 | D14: 한양 이유한·김현욱
B15: 팀장·파트장(명) | C15: =COUNTIF(인원명부!$K$5:$K$105,"?*") -> 28 | D15: 원자료 (팀장)·(파트장) 표기 기준
B16: 최다 인원 학교 | C16: =INDEX(학교별!B5:B49,MATCH(MAX(학교별!D5:D49),학교별!D5:D49,0)) -> 한양대
B17: 최다 인원 학교 인원(명) | C17: =MAX(학교별!D5:D49) -> 11
B18: 최다 인원 업체 | C18: =INDEX(업체별!B5:B35,MATCH(MAX(업체별!C5:C35),업체별!C5:C35,0)) -> 대보
B19: 최다 인원 업체 인원(명) | C19: =MAX(업체별!C5:C35) -> 8
B20: 확인 필요 건수 | C20: =COUNTIF(인원명부!$P$5:$P$105,"*확인 필요*") -> 4 | D20: 상세: 자료대조 시트
B22: 표기 안내
C23: 임원(인원명부 업체·직급구분 열)
C24: 팀장·파트장(인원명부 직책 열)
C25: 자료 간 표기 상이 → 확인 필요(인원명부 비고 열)
B27: 시트 구성
B28: 인원명부: 101명 전체 명단(필터 가능)
B29: 년생별: 66~85년생 인원·임원·명단
B30: 업체별: 31개사 인원·임원·명단
B31: 학교별: 대표학교 기준 인원·지역·명단
B32: 자료대조: 원자료 4건 비교 및 확인 필요 사항

Sheet 인원명부
A1: 공공건축 동종업계 인원명부 (최종)
A2: 작성일 2026-10-08 · 정렬: 년생 → 임원 우선 · 연나이 = 기준연도(요약!C5) − 출생연도
A4: 순번 | B4: 년생 | C4: 빠른 년생 | D4: 연나이 | E4: 띠 | F4: 업체 (표준) | G4: 원자료 업체표기 | H4: 성명 | I4: 직급 | J4: 직급구분 | K4: 직책 | L4: 대표학교 | M4: 출신학교 (원자료 전체) | N4: 학교지역 | O4: 자료출처 | P4: 비고
A5: 1 | B5: 66 | D5: =요약!$C$5-(1900+B5) -> 60 | E5: 말띠 | F5: 남광 | G5: 남광 | H5: 허정호 | I5: 부사장 | J5: 임원 | L5: 수원대 | M5: 수원대/성균관대 | O5: 엑셀(가로)·현황PDF(100건)
A6: 2 | B6: 66 | D6: =요약!$C$5-(1900+B6) -> 60 | E6: 말띠 | F6: KR | G6: KR | H6: 조판철 | I6: 상무 | J6: 임원 | L6: 한밭대 | M6: 한밭대 | N6: 대전·충청 | O6: 엑셀(가로)·현황PDF(100건)
A7: 3 | B7: 66 | D7: =요약!$C$5-(1900+B7) -> 60 | E7: 말띠 | F7: 대보 | G7: 대보 | H7: 정재수 | I7: 전무 | J7: 임원 | L7: 한양대 | M7: 한양대 | N7: 서울 | O7: 엑셀(가로)·현황PDF(100건)
A8: 4 | B8: 66 | D8: =요약!$C$5-(1900+B8) -> 60 | E8: 말띠 | F8: 태영 | G8: 태영 | H8: 정진형 | I8: 전무 | J8: 임원 | L8: 경희대 | M8: 경희대 | N8: 서울 | O8: 엑셀(가로)·현황PDF(100건)
A9: 5 | B9: 66 | D9: =요약!$C$5-(1900+B9) -> 60 | E9: 말띠 | F9: 포스코 | G9: 포스코 | H9: 박종진 | I9: 전무 | J9: 임원 | L9: 고려대 | M9: 고려대 | N9: 서울 | O9: 엑셀(가로)·현황PDF(100건)
A10: 6 | B10: 69 | D10: =요약!$C$5-(1900+B10) -> 57 | E10: 닭띠 | F10: 한양 | G10: 한양 | H10: 조훈 | I10: 상무 | J10: 임원 | L10: 중앙대 | M10: 중앙대 | N10: 서울 | O10: 엑셀(가로)·현황PDF(100건) | P10: 학교별분석PDF 미포함(집계 제외 인원).
A11: 7 | B11: 70 | C11: 빠른 | D11: =요약!$C$5-(1900+B11) -> 56 | E11: 개띠 | F11: 대우 | G11: 대우 | H11: 김용 | I11: 상무 | J11: 임원 | L11: 한양대 | M11: 한양대 | N11: 서울 | O11: 엑셀(가로)·현황PDF(100건)
A12: 8 | B12: 70 | D12: =요약!$C$5-(1900+B12) -> 56 | E12: 개띠 | F12: 동부 | G12: 동부 | H12: 김희석 | I12: 전무 | J12: 임원 | L12: 명지대 | M12: 명지대 | N12: 서울 | O12: 엑셀(가로)·현황PDF(100건)
A13: 9 | B13: 70 | D13: =요약!$C$5-(1900+B13) -> 56 | E13: 개띠 | F13: 금강 | G13: 금강 | H13: 위현복 | I13: 상무 | J13: 임원 | L13: 광운대 | M13: 광운대 | N13: 서울 | O13: 엑셀(가로)·현황PDF(100건)
A14: 10 | B14: 70 | D14: =요약!$C$5-(1900+B14) -> 56 | E14: 개띠 | F14: 한신 | G14: 한신 | H14: 조규용 | I14: 상무 | J14: 임원 | L14: 원광대 | M14: 원광대 | O14: 엑셀(가로)·현황PDF(100건)
A15: 11 | B15: 70 | D15: =요약!$C$5-(1900+B15) -> 56 | E15: 개띠 | F15: 우미 | G15: 우미 | H15: 김형일 | I15: 전무 | J15: 임원 | L15: 광운대 | M15: 광운대 | N15: 서울 | O15: 엑셀(가로)·현황PDF(100건)
A16: 12 | B16: 70 | D16: =요약!$C$5-(1900+B16) -> 56 | E16: 개띠 | F16: 서희 | G16: 서희 | H16: 임흥식 | I16: 전무 | J16: 임원 | L16: 경일대 | M16: 경일대 | N16: 대구·경북 | O16: 엑셀(가로)·현황PDF(100건)
A17: 13 | B17: 70 | C17: 빠른 | D17: =요약!$C$5-(1900+B17) -> 56 | E17: 개띠 | F17: 금호 | G17: 금호 | H17: 신재혁 | I17: 전무 | J17: 임원 | L17: 아주대 | M17: 아주대 | N17: 경기·인천 | O17: 엑셀(가로)·현황PDF(100건)
A18: 14 | B18: 71 | D18: =요약!$C$5-(1900+B18) -> 55 | E18: 돼지띠 | F18: 계룡 | G18: 계룡 | H18: 전병규 | I18: 상무 | J18: 임원 | L18: 한밭대 | M18: 한밭대 | N18: 대전·충청 | O18: 엑셀(가로)·현황PDF(100건)
A19: 15 | B19: 71 | D19: =요약!$C$5-(1900+B19) -> 55 | E19: 돼지띠 | F19: HJ중공업 | G19: HJ중공업 | H19: 정회경 | I19: 상무 | J19: 임원 | L19: 한양대 | M19: 한양대 | N19: 서울 | O19: 엑셀(가로)·현황PDF(100건)
A20: 16 | B20: 72 | C20: 빠른 | D20: =요약!$C$5-(1900+B20) -> 54 | E20: 쥐띠 | F20: 계룡 | G20: 계룡 | H20: 강희관 | I20: 상무 | J20: 임원 | L20: 충남대 | M20: 충남대 | N20: 대전·충청 | O20: 엑셀(가로)·현황PDF(100건)
A21: 17 | B21: 72 | D21: =요약!$C$5-(1900+B21) -> 54 | E21: 쥐띠 | F21: 진흥 | G21: 진흥 | H21: 김준기 | I21: 상무 | J21: 임원 | L21: 인하대 | M21: 인하대 | N21: 경기·인천 | O21: 엑셀(가로)·현황PDF(100건)
A22: 18 | B22: 72 | D22: =요약!$C$5-(1900+B22) -> 54 | E22: 쥐띠 | F22: 태영 | G22: 태영 | H22: 우기수 | I22: 상무 | J22: 임원 | L22: 경상대 | M22: 경상대 | O22: 엑셀(가로)·현황PDF(100건)
A23: 19 | B23: 73 | D23: =요약!$C$5-(1900+B23) -> 53 | E23: 소띠 | F23: 극동 | G23: 극동 | H23: 박한섭 | I23: 전무 | J23: 임원 | L23: 건국대 | M23: 건국대 | N23: 서울 | O23: 엑셀(가로)·현황PDF(100건)
A24: 20 | B24: 73 | D24: =요약!$C$5-(1900+B24) -> 53 | E24: 소띠 | F24: 남광 | G24: 남광 | H24: 남도현 | I24: 상무 | J24: 임원 | L24: 서울과기대 | M24: 서울과기대 | N24: 서울 | O24: 엑셀(가로)·현황PDF(100건)
A25: 21 | B25: 73 | D25: =요약!$C$5-(1900+B25) -> 53 | E25: 소띠 | F25: HJ중공업 | G25: HJ중공업 | H25: 김건용 | I25: 상무 | J25: 임원 | L25: 서울시립대 | M25: 서울시립대 | N25: 서울 | O25: 엑셀(가로)·현황PDF(100건)
A26: 22 | B26: 73 | D26: =요약!$C$5-(1900+B26) -> 53 | E26: 소띠 | F26: 대보 | G26: 대보 | H26: 손익창 | I26: 상무 | J26: 임원 | L26: 홍익대 | M26: 홍익대 | N26: 서울 | O26: 엑셀(가로)·현황PDF(100건)
A27: 23 | B27: 73 | D27: =요약!$C$5-(1900+B27) -> 53 | E27: 소띠 | F27: 서한 | G27: 서한 | H27: 김성우 | I27: 이사 | J27: 임원 | L27: 경일대 | M27: 경일대 | N27: 대구·경북 | O27: 엑셀(가로)·현황PDF(100건)
A28: 24 | B28: 73 | D28: =요약!$C$5-(1900+B28) -> 53 | E28: 소띠 | F28: 코오롱 | G28: 코오롱 | H28: 신윤선 | I28: 상무 | J28: 임원 | L28: 고려대 | M28: 고려대 | N28: 서울 | O28: 엑셀(가로)·현황PDF(100건)
A29: 25 | B29: 73 | D29: =요약!$C$5-(1900+B29) -> 53 | E29: 소띠 | F29: 동부 | G29: 동부 | H29: 김종표 | I29: 상무 | J29: 임원 | K29: 팀장 | L29: 명지대 | M29: 명지대 | N29: 서울 | O29: 엑셀(가로)·현황PDF(100건)
A30: 26 | B30: 73 | D30: =요약!$C$5-(1900+B30) -> 53 | E30: 소띠 | F30: 동부 | G30: 동부 | H30: 정필교 | I30: 상무 | J30: 임원 | K30: 팀장 | L30: 서울대 | M30: 서울대 | O30: 엑셀(가로)·현황PDF(100건)
A31: 27 | B31: 73 | D31: =요약!$C$5-(1900+B31) -> 53 | E31: 소띠 | F31: 신동아 | G31: 신동아 | H31: 최경식 | I31: 상무 | J31: 임원 | L31: 영남대 | M31: 영남대 | N31: 대구·경북 | O31: 엑셀(가로)·현황PDF(100건)
A32: 28 | B32: 73 | D32: =요약!$C$5-(1900+B32) -> 53 | E32: 소띠 | F32: 한화 | G32: 한화 | H32: 박영철 | I32: 부장 | J32: 부장 이하 | L32: 조선대 | M32: 조선대/전남대 | N32: 호남·강원 | O32: 엑셀(가로)·현황PDF(100건)
A33: 29 | B33: 73 | D33: =요약!$C$5-(1900+B33) -> 53 | E33: 소띠 | F33: 한신 | G33: 한신 | H33: 김용진 | I33: 부장 | J33: 부장 이하 | K33: 팀장 | L33: 숭실대 | M33: 숭실대 | N33: 서울 | O33: 엑셀(가로)·현황PDF(100건)
A34: 30 | B34: 73 | D34: =요약!$C$5-(1900+B34) -> 53 | E34: 소띠 | F34: GS | G34: GS | H34: 성중규 | I34: 부장 | J34: 부장 이하 | L34: 한양대 | M34: 한양대 | N34: 서울 | O34: 엑셀(가로)·현황PDF(100건) | P34: 학교별분석PDF 미포함(집계 제외 인원).
A35: 31 | B35: 73 | D35: =요약!$C$5-(1900+B35) -> 53 | E35: 소띠 | F35: 대보 | G35: 대보 | H35: 양진영 | I35: 부장 | J35: 부장 이하 | M35: 국방부 | O35: 엑셀(가로)·현황PDF(100건) | P35: 원자료 학교란 "국방부" 표기. 출신학교 미확인.
A36: 32 | B36: 74 | D36: =요약!$C$5-(1900+B36) -> 52 | E36: 호랑이띠 | F36: DL이앤씨 | G36: DL이앤씨 | H36: 박창용 | I36: 실장 | J36: 임원 | L36: 고려대 | M36: 고려대 | N36: 서울 | O36: 엑셀(가로)·현황PDF(100건)
A37: 33 | B37: 74 | D37: =요약!$C$5-(1900+B37) -> 52 | E37: 호랑이띠 | F37: GS | G37: GS | H37: 박재범 | I37: 부장 | J37: 부장 이하 | K37: 팀장 | L37: 서울과기대 | M37: 서울과기대 | N37: 서울 | O37: 엑셀(가로)·현황PDF(100건)
A38: 34 | B38: 74 | D38: =요약!$C$5-(1900+B38) -> 52 | E38: 호랑이띠 | F38: HJ중공업 | G38: HJ중공업 | H38: 김성용 | I38: 부장 | J38: 부장 이하 | L38: 인하대 | M38: 인하대/아주대 | N38: 경기·인천 | O38: 엑셀(가로)·현황PDF(100건)
A39: 35 | B39: 74 | D39: =요약!$C$5-(1900+B39) -> 52 | E39: 호랑이띠 | F39: HJ중공업 | G39: HJ중공업 | H39: 김준의 | I39: 부장 | J39: 부장 이하 | L39: 경성대 | M39: 경성대/부산대 | O39: 엑셀(가로)·현황PDF(100건)
A40: 36 | B40: 75 | D40: =요약!$C$5-(1900+B40) -> 51 | E40: 토끼띠 | F40: 우미 | G40: 우미 | H40: 김철호 | I40: 상무 | J40: 임원 | L40: 광운대 | M40: 광운대 | N40: 서울 | O40: 엑셀(가로)·현황PDF(100건)
A41: 37 | B41: 75 | D41: =요약!$C$5-(1900+B41) -> 51 | E41: 토끼띠 | F41: 이수 | G41: 이수 | H41: 최병훈 | I41: 이사 | J41: 임원 | K41: 팀장 | L41: 세종대 | M41: 세종대/건국대 | N41: 서울 | O41: 엑셀(가로)·현황PDF(100건)
...

Sheet 년생별
A1: 년생별 현황
A2: 출처: 인원명부 시트 집계(COUNTIF 수식) · 띠는 원자료 표기
A4: 년생 | B4: 연나이 | C4: 띠 | D4: 인원 | E4: 임원 | F4: 부장 이하 | G4: 팀장·파트장 | H4: 명단 (업체 성명 직급)
A5: 66 | B5: =요약!$C$5-(1900+A5) -> 60 | C5: 말띠 | D5: =COUNTIF(인원명부!$B$5:$B$105,A5) -> 5 | E5: =COUNTIFS(인원명부!$B$5:$B$105,A5,인원명부!$J$5:$J$105,"임원") -> 5 | F5: =COUNTIFS(인원명부!$B$5:$B$105,A5,인원명부!$J$5:$J$105,"부장 이하") -> 0 | G5: =COUNTIFS(인원명부!$B$5:$B$105,A5,인원명부!$K$5:$K$105,"?*") -> 0 | H5: 남광 허정호 부사장, KR 조판철 상무, 대보 정재수 전무, 태영 정진형 전무, 포스코 박종진 전무
A6: 67 | B6: =요약!$C$5-(1900+A6) -> 59 | C6: 양띠 | D6: =COUNTIF(인원명부!$B$5:$B$105,A6) -> 0 | E6: =COUNTIFS(인원명부!$B$5:$B$105,A6,인원명부!$J$5:$J$105,"임원") -> 0 | F6: =COUNTIFS(인원명부!$B$5:$B$105,A6,인원명부!$J$5:$J$105,"부장 이하") -> 0 | G6: =COUNTIFS(인원명부!$B$5:$B$105,A6,인원명부!$K$5:$K$105,"?*") -> 0 | H6: -
A7: 68 | B7: =요약!$C$5-(1900+A7) -> 58 | C7: 원숭이띠 | D7: =COUNTIF(인원명부!$B$5:$B$105,A7) -> 0 | E7: =COUNTIFS(인원명부!$B$5:$B$105,A7,인원명부!$J$5:$J$105,"임원") -> 0 | F7: =COUNTIFS(인원명부!$B$5:$B$105,A7,인원명부!$J$5:$J$105,"부장 이하") -> 0 | G7: =COUNTIFS(인원명부!$B$5:$B$105,A7,인원명부!$K$5:$K$105,"?*") -> 0 | H7: -
A8: 69 | B8: =요약!$C$5-(1900+A8) -> 57 | C8: 닭띠 | D8: =COUNTIF(인원명부!$B$5:$B$105,A8) -> 1 | E8: =COUNTIFS(인원명부!$B$5:$B$105,A8,인원명부!$J$5:$J$105,"임원") -> 1 | F8: =COUNTIFS(인원명부!$B$5:$B$105,A8,인원명부!$J$5:$J$105,"부장 이하") -> 0 | G8: =COUNTIFS(인원명부!$B$5:$B$105,A8,인원명부!$K$5:$K$105,"?*") -> 0 | H8: 한양 조훈 상무
A9: 70 | B9: =요약!$C$5-(1900+A9) -> 56 | C9: 개띠 | D9: =COUNTIF(인원명부!$B$5:$B$105,A9) -> 7 | E9: =COUNTIFS(인원명부!$B$5:$B$105,A9,인원명부!$J$5:$J$105,"임원") -> 7 | F9: =COUNTIFS(인원명부!$B$5:$B$105,A9,인원명부!$J$5:$J$105,"부장 이하") -> 0 | G9: =COUNTIFS(인원명부!$B$5:$B$105,A9,인원명부!$K$5:$K$105,"?*") -> 0 | H9: 대우 김용 상무, 동부 김희석 전무, 금강 위현복 상무, 한신 조규용 상무, 우미 김형일 전무, 서희 임흥식 전무, 금호 신재혁 전무
A10: 71 | B10: =요약!$C$5-(1900+A10) -> 55 | C10: 돼지띠 | D10: =COUNTIF(인원명부!$B$5:$B$105,A10) -> 2 | E10: =COUNTIFS(인원명부!$B$5:$B$105,A10,인원명부!$J$5:$J$105,"임원") -> 2 | F10: =COUNTIFS(인원명부!$B$5:$B$105,A10,인원명부!$J$5:$J$105,"부장 이하") -> 0 | G10: =COUNTIFS(인원명부!$B$5:$B$105,A10,인원명부!$K$5:$K$105,"?*") -> 0 | H10: 계룡 전병규 상무, HJ중공업 정회경 상무
A11: 72 | B11: =요약!$C$5-(1900+A11) -> 54 | C11: 쥐띠 | D11: =COUNTIF(인원명부!$B$5:$B$105,A11) -> 3 | E11: =COUNTIFS(인원명부!$B$5:$B$105,A11,인원명부!$J$5:$J$105,"임원") -> 3 | F11: =COUNTIFS(인원명부!$B$5:$B$105,A11,인원명부!$J$5:$J$105,"부장 이하") -> 0 | G11: =COUNTIFS(인원명부!$B$5:$B$105,A11,인원명부!$K$5:$K$105,"?*") -> 0 | H11: 계룡 강희관 상무, 진흥 김준기 상무, 태영 우기수 상무
A12: 73 | B12: =요약!$C$5-(1900+A12) -> 53 | C12: 소띠 | D12: =COUNTIF(인원명부!$B$5:$B$105,A12) -> 13 | E12: =COUNTIFS(인원명부!$B$5:$B$105,A12,인원명부!$J$5:$J$105,"임원") -> 9 | F12: =COUNTIFS(인원명부!$B$5:$B$105,A12,인원명부!$J$5:$J$105,"부장 이하") -> 4 | G12: =COUNTIFS(인원명부!$B$5:$B$105,A12,인원명부!$K$5:$K$105,"?*") -> 3 | H12: 극동 박한섭 전무, 남광 남도현 상무, HJ중공업 김건용 상무, 대보 손익창 상무, 서한 김성우 이사, 코오롱 신윤선 상무, 동부 김종표 상무, 동부 정필교 상무, 신동아 최경식 상무, 한화 박영철 부장, 한신 김용진 부장, GS 성중규 부장, 대보 양진영 부장
A13: 74 | B13: =요약!$C$5-(1900+A13) -> 52 | C13: 호랑이띠 | D13: =COUNTIF(인원명부!$B$5:$B$105,A13) -> 4 | E13: =COUNTIFS(인원명부!$B$5:$B$105,A13,인원명부!$J$5:$J$105,"임원") -> 1 | F13: =COUNTIFS(인원명부!$B$5:$B$105,A13,인원명부!$J$5:$J$105,"부장 이하") -> 3 | G13: =COUNTIFS(인원명부!$B$5:$B$105,A13,인원명부!$K$5:$K$105,"?*") -> 1 | H13: DL이앤씨 박창용 실장, GS 박재범 부장, HJ중공업 김성용 부장, HJ중공업 김준의 부장
A14: 75 | B14: =요약!$C$5-(1900+A14) -> 51 | C14: 토끼띠 | D14: =COUNTIF(인원명부!$B$5:$B$105,A14) -> 4 | E14: =COUNTIFS(인원명부!$B$5:$B$105,A14,인원명부!$J$5:$J$105,"임원") -> 2 | F14: =COUNTIFS(인원명부!$B$5:$B$105,A14,인원명부!$J$5:$J$105,"부장 이하") -> 2 | G14: =COUNTIFS(인원명부!$B$5:$B$105,A14,인원명부!$K$5:$K$105,"?*") -> 3 | H14: 우미 김철호 상무, 이수 최병훈 이사, 한화 송원영 부장, 금강 이준성 부장
A15: 76 | B15: =요약!$C$5-(1900+A15) -> 50 | C15: 용띠 | D15: =COUNTIF(인원명부!$B$5:$B$105,A15) -> 12 | E15: =COUNTIFS(인원명부!$B$5:$B$105,A15,인원명부!$J$5:$J$105,"임원") -> 3 | F15: =COUNTIFS(인원명부!$B$5:$B$105,A15,인원명부!$J$5:$J$105,"부장 이하") -> 8 | G15: =COUNTIFS(인원명부!$B$5:$B$105,A15,인원명부!$K$5:$K$105,"?*") -> 7 | H15: DL이앤씨 박은철 상무, 금호 김찬식 상무, 대보 하승훈 상무, 대우 박민혁 책임, 동부 손규홍 부장, 극동 이진만 부장, 대보 김홍석 부장, 서한 길동영 부장, 한양 이유한, 진흥 김동현 부장, 남광 박주현 부장, 계룡 김동식 부장
A16: 77 | B16: =요약!$C$5-(1900+A16) -> 49 | C16: 뱀띠 | D16: =COUNTIF(인원명부!$B$5:$B$105,A16) -> 3 | E16: =COUNTIFS(인원명부!$B$5:$B$105,A16,인원명부!$J$5:$J$105,"임원") -> 0 | F16: =COUNTIFS(인원명부!$B$5:$B$105,A16,인원명부!$J$5:$J$105,"부장 이하") -> 3 | G16: =COUNTIFS(인원명부!$B$5:$B$105,A16,인원명부!$K$5:$K$105,"?*") -> 0 | H16: DL이앤씨 송영찬 부장, 진흥 조성필 차장, 금강 유태현 부장
... A24: 85 | B24: =요약!$C$5-(1900+A24) -> 41 | C24: 소띠 | D24: =COUNTIF(인원명부!$B$5:$B$105,A24) -> 1 | E24: =COUNTIFS(인원명부!$B$5:$B$105,A24,인원명부!$J$5:$J$105,"임원") -> 0 | F24: =COUNTIFS(인원명부!$B$5:$B$105,A24,인원명부!$J$5:$J$105,"부장 이하") -> 1 | G24: =COUNTIFS(인원명부!$B$5:$B$105,A24,인원명부!$K$5:$K$105,"?*") -> 0 | H24: HJ중공업 이상범 과장
A25: 합계 | D25: =SUM(D5:D24) -> 101 | E25: =SUM(E5:E24) -> 33 | F25: =SUM(F5:F24) -> 66 | G25: =SUM(G5:G24) -> 28

Sheet 업체별
A1: 업체별 현황
A2: 출처: 인원명부 시트 집계 · 업체명은 현황 PDF 표기 기준으로 표준화(예: 동부건설→동부, HJ→HJ중공업)
A4: 순위 | B4: 업체 | C4: 인원 | D4: 임원 | E4: 부장 이하 | F4: 팀장·파트장 | G4: 명단 (성명 직급 년생)
A5: =RANK(C5,$C$5:$C$35) -> 1 | B5: 대보 | C5: =COUNTIF(인원명부!$F$5:$F$105,B5) -> 8 | D5: =COUNTIFS(인원명부!$F$5:$F$105,B5,인원명부!$J$5:$J$105,"임원") -> 3 | E5: =COUNTIFS(인원명부!$F$5:$F$105,B5,인원명부!$J$5:$J$105,"부장 이하") -> 5 | F5: =COUNTIFS(인원명부!$F$5:$F$105,B5,인원명부!$K$5:$K$105,"?*") -> 2 | G5: 정재수 전무(66), 손익창 상무(73), 양진영 부장(73), 하승훈 상무(76), 김홍석 부장(76), 차대희 부장(80), 박정석 차장(81), 정영호 차장(84)
A6: =RANK(C6,$C$5:$C$35) -> 2 | B6: 동부 | C6: =COUNTIF(인원명부!$F$5:$F$105,B6) -> 7 | D6: =COUNTIFS(인원명부!$F$5:$F$105,B6,인원명부!$J$5:$J$105,"임원") -> 3 | E6: =COUNTIFS(인원명부!$F$5:$F$105,B6,인원명부!$J$5:$J$105,"부장 이하") -> 4 | F6: =COUNTIFS(인원명부!$F$5:$F$105,B6,인원명부!$K$5:$K$105,"?*") -> 2 | G6: 김희석 전무(70), 김종표 상무(73), 정필교 상무(73), 손규홍 부장(76), 김성호 부장(78), 김대건 차장(83), 정훈기 차장(83)
A7: =RANK(C7,$C$5:$C$35) -> 2 | B7: HJ중공업 | C7: =COUNTIF(인원명부!$F$5:$F$105,B7) -> 7 | D7: =COUNTIFS(인원명부!$F$5:$F$105,B7,인원명부!$J$5:$J$105,"임원") -> 2 | E7: =COUNTIFS(인원명부!$F$5:$F$105,B7,인원명부!$J$5:$J$105,"부장 이하") -> 5 | F7: =COUNTIFS(인원명부!$F$5:$F$105,B7,인원명부!$K$5:$K$105,"?*") -> 0 | G7: 정회경 상무(71), 김건용 상무(73), 김성용 부장(74), 김준의 부장(74), 라영철 차장(78), 이범석 부장(81), 이상범 과장(85)
A8: =RANK(C8,$C$5:$C$35) -> 2 | B8: 계룡 | C8: =COUNTIF(인원명부!$F$5:$F$105,B8) -> 7 | D8: =COUNTIFS(인원명부!$F$5:$F$105,B8,인원명부!$J$5:$J$105,"임원") -> 2 | E8: =COUNTIFS(인원명부!$F$5:$F$105,B8,인원명부!$J$5:$J$105,"부장 이하") -> 5 | F8: =COUNTIFS(인원명부!$F$5:$F$105,B8,인원명부!$K$5:$K$105,"?*") -> 3 | G8: 전병규 상무(71), 강희관 상무(72), 김동식 부장(76), 사용기 부장(79), 오병한 부장(80), 권세호 차장(82), 송원한 차장(82)
A9: =RANK(C9,$C$5:$C$35) -> 5 | B9: DL이앤씨 | C9: =COUNTIF(인원명부!$F$5:$F$105,B9) -> 6 | D9: =COUNTIFS(인원명부!$F$5:$F$105,B9,인원명부!$J$5:$J$105,"임원") -> 2 | E9: =COUNTIFS(인원명부!$F$5:$F$105,B9,인원명부!$J$5:$J$105,"부장 이하") -> 4 | F9: =COUNTIFS(인원명부!$F$5:$F$105,B9,인원명부!$K$5:$K$105,"?*") -> 1 | G9: 박창용 실장(74), 박은철 상무(76), 송영찬 부장(77), 안홍주 부장(79), 정태왕 부장(80), 이석현 부장(82)
A10: =RANK(C10,$C$5:$C$35) -> 5 | B10: 금호 | C10: =COUNTIF(인원명부!$F$5:$F$105,B10) -> 6 | D10: =COUNTIFS(인원명부!$F$5:$F$105,B10,인원명부!$J$5:$J$105,"임원") -> 2 | E10: =COUNTIFS(인원명부!$F$5:$F$105,B10,인원명부!$J$5:$J$105,"부장 이하") -> 4 | F10: =COUNTIFS(인원명부!$F$5:$F$105,B10,인원명부!$K$5:$K$105,"?*") -> 2 | G10: 신재혁 전무(70), 김찬식 상무(76), 강훈모 수석매니저(79), 허림 수석매니저(80), 김수희 수석매니저(81), 이경은 수석매니저(81)
A11: =RANK(C11,$C$5:$C$35) -> 7 | B11: GS | C11: =COUNTIF(인원명부!$F$5:$F$105,B11) -> 5 | D11: =COUNTIFS(인원명부!$F$5:$F$105,B11,인원명부!$J$5:$J$105,"임원") -> 0 | E11: =COUNTIFS(인원명부!$F$5:$F$105,B11,인원명부!$J$5:$J$105,"부장 이하") -> 5 | F11: =COUNTIFS(인원명부!$F$5:$F$105,B11,인원명부!$K$5:$K$105,"?*") -> 1 | G11: 성중규 부장(73), 박재범 부장(74), 서해두 부장(82), 김태우 부장(82), 정가람 차장(84)
A12: =RANK(C12,$C$5:$C$35) -> 8 | B12: 태영 | C12: =COUNTIF(인원명부!$F$5:$F$105,B12) -> 4 | D12: =COUNTIFS(인원명부!$F$5:$F$105,B12,인원명부!$J$5:$J$105,"임원") -> 2 | E12: =COUNTIFS(인원명부!$F$5:$F$105,B12,인원명부!$J$5:$J$105,"부장 이하") -> 2 | F12: =COUNTIFS(인원명부!$F$5:$F$105,B12,인원명부!$K$5:$K$105,"?*") -> 1 | G12: 정진형 전무(66), 우기수 상무(72), 박석현 부장(78), 백건구 차장(82)
A13: =RANK(C13,$C$5:$C$35) -> 8 | B13: 금강 | C13: =COUNTIF(인원명부!$F$5:$F$105,B13) -> 4 | D13: =COUNTIFS(인원명부!$F$5:$F$105,B13,인원명부!$J$5:$J$105,"임원") -> 1 | E13: =COUNTIFS(인원명부!$F$5:$F$105,B13,인원명부!$J$5:$J$105,"부장 이하") -> 3 | F13: =COUNTIFS(인원명부!$F$5:$F$105,B13,인원명부!$K$5:$K$105,"?*") -> 1 | G13: 위현복 상무(70), 이준성 부장(75), 유태현 부장(77), 안현민 차장(82)
A14: =RANK(C14,$C$5:$C$35) -> 8 | B14: 한양 | C14: =COUNTIF(인원명부!$F$5:$F$105,B14) -> 4 | D14: =COUNTIFS(인원명부!$F$5:$F$105,B14,인원명부!$J$5:$J$105,"임원") -> 1 | E14: =COUNTIFS(인원명부!$F$5:$F$105,B14,인원명부!$J$5:$J$105,"부장 이하") -> 1 | F14: =COUNTIFS(인원명부!$F$5:$F$105,B14,인원명부!$K$5:$K$105,"?*") -> 1 | G14: 조훈 상무(69), 이유한(76), 김현욱(78), 임재경 차장(81)
A15: =RANK(C15,$C$5:$C$35) -> 8 | B15: 한화 | C15: =COUNTIF(인원명부!$F$5:$F$105,B15) -> 4 | D15: =COUNTIFS(인원명부!$F$5:$F$105,B15,인원명부!$J$5:$J$105,"임원") -> 0 | E15: =COUNTIFS(인원명부!$F$5:$F$105,B15,인원명부!$J$5:$J$105,"부장 이하") -> 4 | F15: =COUNTIFS(인원명부!$F$5:$F$105,B15,인원명부!$K$5:$K$105,"?*") -> 1 | G15: 박영철 부장(73), 송원영 부장(75), 차원재 차장(83), 하현성 차장(84)
A16: =RANK(C16,$C$5:$C$35) -> 12 | B16: 남광 | C16: =COUNTIF(인원명부!$F$5:$F$105,B16) -> 3 | D16: =COUNTIFS(인원명부!$F$5:$F$105,B16,인원명부!$J$5:$J$105,"임원") -> 2 | E16: =COUNTIFS(인원명부!$F$5:$F$105,B16,인원명부!$J$5:$J$105,"부장 이하") -> 1 | F16: =COUNTIFS(인원명부!$F$5:$F$105,B16,인원명부!$K$5:$K$105,"?*") -> 1 | G16: 허정호 부사장(66), 남도현 상무(73), 박주현 부장(76)
... A35: =RANK(C35,$C$5:$C$35) -> 23 | B35: 현대ENG | C35: =COUNTIF(인원명부!$F$5:$F$105,B35) -> 1 | D35: =COUNTIFS(인원명부!$F$5:$F$105,B35,인원명부!$J$5:$J$105,"임원") -> 0 | E35: =COUNTIFS(인원명부!$F$5:$F$105,B35,인원명부!$J$5:$J$105,"부장 이하") -> 1 | F35: =COUNTIFS(인원명부!$F$5:$F$105,B35,인원명부!$K$5:$K$105,"?*") -> 0 | G35: 이진혁 차장(83)
B36: 합계 | C36: =SUM(C5:C35) -> 101 | D36: =SUM(D5:D35) -> 33 | E36: =SUM(E5:E35) -> 66 | F36: =SUM(F5:F35) -> 28

Sheet 학교별
A1: 학교별 현황
A2: 출처: 인원명부 대표학교 기준 집계 · 대표학교·지역은 학교별 분석 PDF 분류 준용 · 지역 공란 = 원자료 미기재
A4: 순위 | B4: 학교 | C4: 지역 | D4: 인원 | E4: 임원 | F4: 부장 이하 | G4: 명단 (업체 성명 직급 년생)
A5: =RANK(D5,$D$5:$D$49) -> 1 | B5: 한양대 | C5: 서울 | D5: =COUNTIF(인원명부!$L$5:$L$105,B5) -> 11 | E5: =COUNTIFS(인원명부!$L$5:$L$105,B5,인원명부!$J$5:$J$105,"임원") -> 3 | F5: =COUNTIFS(인원명부!$L$5:$L$105,B5,인원명부!$J$5:$J$105,"부장 이하") -> 7 | G5: 대보 정재수 전무(66), 대우 김용 상무(70), HJ중공업 정회경 상무(71), GS 성중규 부장(73), 한화 송원영 부장(75), 한양 이유한(76), 태영 박석현 부장(78), 우미 배성민 부장(80), 금백 이규호 차장(81), 동부 김대건 차장(83), 현대 이호창 책임매니저(84)
A6: =RANK(D6,$D$5:$D$49) -> 2 | B6: 인하대 | C6: 경기·인천 | D6: =COUNTIF(인원명부!$L$5:$L$105,B6) -> 5 | E6: =COUNTIFS(인원명부!$L$5:$L$105,B6,인원명부!$J$5:$J$105,"임원") -> 1 | F6: =COUNTIFS(인원명부!$L$5:$L$105,B6,인원명부!$J$5:$J$105,"부장 이하") -> 4 | G6: 진흥 김준기 상무(72), HJ중공업 김성용 부장(74), 진흥 조성필 차장(77), HJ중공업 이범석 부장(81), 계룡 권세호 차장(82)
A7: =RANK(D7,$D$5:$D$49) -> 3 | B7: 고려대 | C7: 서울 | D7: =COUNTIF(인원명부!$L$5:$L$105,B7) -> 4 | E7: =COUNTIFS(인원명부!$L$5:$L$105,B7,인원명부!$J$5:$J$105,"임원") -> 3 | F7: =COUNTIFS(인원명부!$L$5:$L$105,B7,인원명부!$J$5:$J$105,"부장 이하") -> 1 | G7: 포스코 박종진 전무(66), 코오롱 신윤선 상무(73), DL이앤씨 박창용 실장(74), 동부 김성호 부장(78)
A8: =RANK(D8,$D$5:$D$49) -> 3 | B8: 광운대 | C8: 서울 | D8: =COUNTIF(인원명부!$L$5:$L$105,B8) -> 4 | E8: =COUNTIFS(인원명부!$L$5:$L$105,B8,인원명부!$J$5:$J$105,"임원") -> 3 | F8: =COUNTIFS(인원명부!$L$5:$L$105,B8,인원명부!$J$5:$J$105,"부장 이하") -> 1 | G8: 금강 위현복 상무(70), 우미 김형일 전무(70), 우미 김철호 상무(75), 극동 이진만 부장(76)
A9: =RANK(D9,$D$5:$D$49) -> 3 | B9: 서울과기대 | C9: 서울 | D9: =COUNTIF(인원명부!$L$5:$L$105,B9) -> 4 | E9: =COUNTIFS(인원명부!$L$5:$L$105,B9,인원명부!$J$5:$J$105,"임원") -> 1 | F9: =COUNTIFS(인원명부!$L$5:$L$105,B9,인원명부!$J$5:$J$105,"부장 이하") -> 3 | G9: 남광 남도현 상무(73), GS 박재범 부장(74), 금호 이경은 수석매니저(81), DL건설 하동우 부장(82)
A10: =RANK(D10,$D$5:$D$49) -> 3 | B10: 숭실대 | C10: 서울 | D10: =COUNTIF(인원명부!$L$5:$L$105,B10) -> 4 | E10: =COUNTIFS(인원명부!$L$5:$L$105,B10,인원명부!$J$5:$J$105,"임원") -> 0 | F10: =COUNTIFS(인원명부!$L$5:$L$105,B10,인원명부!$J$5:$J$105,"부장 이하") -> 4 | G10: 한신 김용진 부장(73), GS 정가람 차장(84), 한화 하현성 차장(84), HJ중공업 이상범 과장(85)
A11: =RANK(D11,$D$5:$D$49) -> 3 | B11: 중앙대 | C11: 서울 | D11: =COUNTIF(인원명부!$L$5:$L$105,B11) -> 4 | E11: =COUNTIFS(인원명부!$L$5:$L$105,B11,인원명부!$J$5:$J$105,"임원") -> 1 | F11: =COUNTIFS(인원명부!$L$5:$L$105,B11,인원명부!$J$5:$J$105,"부장 이하") -> 3 | G11: 한양 조훈 상무(69), 쌍용 전현도 차장(81), DL이앤씨 이석현 부장(82), 이수 김종욱 차장(83)
A12: =RANK(D12,$D$5:$D$49) -> 3 | B12: 영남대 | C12: 대구·경북 | D12: =COUNTIF(인원명부!$L$5:$L$105,B12) -> 4 | E12: =COUNTIFS(인원명부!$L$5:$L$105,B12,인원명부!$J$5:$J$105,"임원") -> 1 | F12: =COUNTIFS(인원명부!$L$5:$L$105,B12,인원명부!$J$5:$J$105,"부장 이하") -> 3 | G12: 신동아 최경식 상무(73), 동부 손규홍 부장(76), 서한 길동영 부장(76), 대보 정영호 차장(84)
A13: =RANK(D13,$D$5:$D$49) -> 9 | B13: 건국대 | C13: 서울 | D13: =COUNTIF(인원명부!$L$5:$L$105,B13) -> 3 | E13: =COUNTIFS(인원명부!$L$5:$L$105,B13,인원명부!$J$5:$J$105,"임원") -> 1 | F13: =COUNTIFS(인원명부!$L$5:$L$105,B13,인원명부!$J$5:$J$105,"부장 이하") -> 2 | G13: 극동 박한섭 전무(73), DL이앤씨 송영찬 부장(77), 태영 백건구 차장(82)
A14: =RANK(D14,$D$5:$D$49) -> 9 | B14: 세종대 | C14: 서울 | D14: =COUNTIF(인원명부!$L$5:$L$105,B14) -> 3 | E14: =COUNTIFS(인원명부!$L$5:$L$105,B14,인원명부!$J$5:$J$105,"임원") -> 1 | F14: =COUNTIFS(인원명부!$L$5:$L$105,B14,인원명부!$J$5:$J$105,"부장 이하") -> 2 | G14: 이수 최병훈 이사(75), 대보 차대희 부장(80), 한신 이상혁 차장(84)
A15: =RANK(D15,$D$5:$D$49) -> 9 | B15: 단국대 | C15: 경기·인천 | D15: =COUNTIF(인원명부!$L$5:$L$105,B15) -> 3 | E15: =COUNTIFS(인원명부!$L$5:$L$105,B15,인원명부!$J$5:$J$105,"임원") -> 1 | F15: =COUNTIFS(인원명부!$L$5:$L$105,B15,인원명부!$J$5:$J$105,"부장 이하") -> 2 | G15: DL이앤씨 박은철 상무(76), 대우 박민혁 책임(76), 신동아 이동하 부장(78)
A16: =RANK(D16,$D$5:$D$49) -> 9 | B16: 아주대 | C16: 경기·인천 | D16: =COUNTIF(인원명부!$L$5:$L$105,B16) -> 3 | E16: =COUNTIFS(인원명부!$L$5:$L$105,B16,인원명부!$J$5:$J$105,"임원") -> 1 | F16: =COUNTIFS(인원명부!$L$5:$L$105,B16,인원명부!$J$5:$J$105,"부장 이하") -> 2 | G16: 금호 신재혁 전무(70), 금호 허림 수석매니저(80), GS 서해두 부장(82)
... A30: =RANK(D30,$D$5:$D$49) -> 14 | B30: 조선대 | C30: 호남·강원 | D30: =COUNTIF(인원명부!$L$5:$L$105,B30) -> 2 | E30: =COUNTIFS(인원명부!$L$5:$L$105,B30,인원명부!$J$5:$J$105,"임원") -> 0 | F30: =COUNTIFS(인원명부!$L$5:$L$105,B30,인원명부!$J$5:$J$105,"부장 이하") -> 2 | G30: 한화 박영철 부장(73), 금강 안현민 차장(82)
A31: =RANK(D31,$D$5:$D$49) -> 27 | B31: 경기대 | D31: =COUNTIF(인원명부!$L$5:$L$105,B31) -> 1 | E31: =COUNTIFS(인원명부!$L$5:$L$105,B31,인원명부!$J$5:$J$105,"임원") -> 0 | F31: =COUNTIFS(인원명부!$L$5:$L$105,B31,인원명부!$J$5:$J$105,"부장 이하") -> 1 | G31: 제일 김재승 차장(83)
A32: =RANK(D32,$D$5:$D$49) -> 27 | B32: 경상대 | D32: =COUNTIF(인원명부!$L$5:$L$105,B32) -> 1 | E32: =COUNTIFS(인원명부!$L$5:$L$105,B32,인원명부!$J$5:$J$105,"임원") -> 1 | F32: =COUNTIFS(인원명부!$L$5:$L$105,B32,인원명부!$J$5:$J$105,"부장 이하") -> 0 | G32: 태영 우기수 상무(72)
A33: =RANK(D33,$D$5:$D$49) -> 27 | B33: 경성대 | D33: =COUNTIF(인원명부!$L$5:$L$105,B33) -> 1 | E33: =COUNTIFS(인원명부!$L$5:$L$105,B33,인원명부!$J$5:$J$105,"임원") -> 0 | F33: =COUNTIFS(인원명부!$L$5:$L$105,B33,인원명부!$J$5:$J$105,"부장 이하") -> 1 | G33: HJ중공업 김준의 부장(74)
A34: =RANK(D34,$D$5:$D$49) -> 27 | B34: 계원예술대 | D34: =COUNTIF(인원명부!$L$5:$L$105,B34) -> 1 | E34: =COUNTIFS(인원명부!$L$5:$L$105,B34,인원명부!$J$5:$J$105,"임원") -> 0 | F34: =COUNTIFS(인원명부!$L$5:$L$105,B34,인원명부!$J$5:$J$105,"부장 이하") -> 0 | G34: 한양 김현욱(78)
A35: =RANK(D35,$D$5:$D$49) -> 27 | B35: 동국대 | D35: =COUNTIF(인원명부!$L$5:$L$105,B35) -> 1 | E35: =COUNTIFS(인원명부!$L$5:$L$105,B35,인원명부!$J$5:$J$105,"임원") -> 1 | F35: =COUNTIFS(인원명부!$L$5:$L$105,B35,인원명부!$J$5:$J$105,"부장 이하") -> 0 | G35: 금호 김찬식 상무(76)
A36: =RANK(D36,$D$5:$D$49) -> 27 | B36: 동아대 | D36: =COUNTIF(인원명부!$L$5:$L$105,B36) -> 1 | E36: =COUNTIFS(인원명부!$L$5:$L$105,B36,인원명부!$J$5:$J$105,"임원") -> 0 | F36: =COUNTIFS(인원명부!$L$5:$L$105,B36,인원명부!$J$5:$J$105,"부장 이하") -> 1 | G36: 진흥 김동현 부장(76)
A37: =RANK(D37,$D$5:$D$49) -> 27 | B37: 동양대 | D37: =COUNTIF(인원명부!$L$5:$L$105,B37) -> 1 | E37: =COUNTIFS(인원명부!$L$5:$L$105,B37,인원명부!$J$5:$J$105,"임원") -> 0 | F37: =COUNTIFS(인원명부!$L$5:$L$105,B37,인원명부!$J$5:$J$105,"부장 이하") -> 1 | G37: KR 차유진 부장(79)
A38: =RANK(D38,$D$5:$D$49) -> 27 | B38: 동의대 | D38: =COUNTIF(인원명부!$L$5:$L$105,B38) -> 1 | E38: =COUNTIFS(인원명부!$L$5:$L$105,B38,인원명부!$J$5:$J$105,"임원") -> 0 | F38: =COUNTIFS(인원명부!$L$5:$L$105,B38,인원명부!$J$5:$J$105,"부장 이하") -> 1 | G38: 한양 임재경 차장(81)
A39: =RANK(D39,$D$5:$D$49) -> 27 | B39: 목원대 | D39: =COUNTIF(인원명부!$L$5:$L$105,B39) -> 1 | E39: =COUNTIFS(인원명부!$L$5:$L$105,B39,인원명부!$J$5:$J$105,"임원") -> 0 | F39: =COUNTIFS(인원명부!$L$5:$L$105,B39,인원명부!$J$5:$J$105,"부장 이하") -> 1 | G39: 극동 차길환 차장(82)
A40: =RANK(D40,$D$5:$D$49) -> 27 | B40: 부경대 | D40: =COUNTIF(인원명부!$L$5:$L$105,B40) -> 1 | E40: =COUNTIFS(인원명부!$L$5:$L$105,B40,인원명부!$J$5:$J$105,"임원") -> 0 | F40: =COUNTIFS(인원명부!$L$5:$L$105,B40,인원명부!$J$5:$J$105,"부장 이하") -> 1 | G40: 대보 김홍석 부장(76)
A41: =RANK(D41,$D$5:$D$49) -> 27 | B41: 서울대 | D41: =COUNTIF(인원명부!$L$5:$L$105,B41) -> 1 | E41: =COUNTIFS(인원명부!$L$5:$L$105,B41,인원명부!$J$5:$J$105,"임원") -> 1 | F41: =COUNTIFS(인원명부!$L$5:$L$105,B41,인원명부!$J$5:$J$105,"부장 이하") -> 0 | G41: 동부 정필교 상무(73)
A42: =RANK(D42,$D$5:$D$49) -> 27 | B42: 선문대 | D42: =COUNTIF(인원명부!$L$5:$L$105,B42) -> 1 | E42: =COUNTIFS(인원명부!$L$5:$L$105,B42,인원명부!$J$5:$J$105,"임원") -> 0 | F42: =COUNTIFS(인원명부!$L$5:$L$105,B42,인원명부!$J$5:$J$105,"부장 이하") -> 1 | G42: 대보 박정석 차장(81)
... A49: =RANK(D49,$D$5:$D$49) -> 27 | B49: 한라대 | D49: =COUNTIF(인원명부!$L$5:$L$105,B49) -> 1 | E49: =COUNTIFS(인원명부!$L$5:$L$105,B49,인원명부!$J$5:$J$105,"임원") -> 0 | F49: =COUNTIFS(인원명부!$L$5:$L$105,B49,인원명부!$J$5:$J$105,"부장 이하") -> 1 | G49: 금강 유태현 부장(77)
B50: 합계 | D50: =SUM(D5:D49) -> 100 | E50: =SUM(E5:E49) -> 33 | F50: =SUM(F5:F49) -> 65
B51: 학교 미확인 | D51: =COUNTIF(인원명부!$L$5:$L$105,"") -> 1 | G51: 대보 양진영 부장(73) - 원자료 학교란 "국방부" 표기

Sheet 자료대조
A1: 원자료 대조 및 확인 필요 사항
A2: 4개 원자료를 인원 단위로 대조한 결과
A4: 구분 | B4: 자료명(파일) | C4: 내용 | D4: 등재 건수 | E4: 비고
A5: ① | B5: 5_6212839703138280666.xlsx (가로 시트) | C5: 년생·연나이·띠·성명(업체/직급/학교) | D5: 100명 | E5: 본 명부의 기본 자료. "세로" 시트는 구버전으로 판단하여 미사용(아래 참조).
A6: ② | B6: public_architecture_full_updated (현황 PDF) | C6: 공공건축 동종업계 현황, 66~84년생 | D6: 100건 / 31개사 | E6: ①과 인원·직급·학교 일치 확인.
A7: ③ | B7: public_architecture_1966_1980_filtered_final (현황 PDF) | C7: ②의 66~80년생 필터본 | D7: 71건 / 25개사 | E7: ②의 부분집합. 별도 차이 없음.
A8: ④ | B8: 5_6213033122695487766 (학교별 분석 PDF) | C8: 학교별 명단·순위 | D8: 94명 / 44개교 | E8: ①·②에 없는 이상범(85년생) 1명 포함. 한양 4명·GS 2명·양진영 등 7명 미포함.
A10: 확인 필요 사항
A11: No | B11: 성명(업체) | C11: 항목 | D11: 자료별 표기 | E11: 본 명부 적용
A12: 1 | B12: 이상범 (HJ중공업) | C12: 등재 여부 | D12: ④에만 등재(85년생·과장·숭실대). ①②③ 미등재. | E12: 명부에 포함(101번째). 자료출처 "학교별분석PDF 단독" 표기.
A13: 2 | B13: 사용기 (계룡) | C13: 출신학교 | D13: ①② 충북대 / ④ 청주대 | E13: 충북대(2개 자료 일치) 적용.
A14: 3 | B14: 이진혁 (현대ENG) | C14: 직급 | D14: ①② 차장 / ④ 책임 | E14: 차장 적용.
A15: 4 | B15: 김태우 (GS) | C15: 년생 | D15: ①② 빠른82(82년생 행) / ④ 81 | E15: 82년생 적용, 빠른년생 표기.
A16: 5 | B16: 유태현 (금강) | C16: 년생 | D16: ① 77년생 행에 "빠른76" 기재 / ② 77년생 / ④ 77 | E16: 77년생 적용, 빠른년생 표기.
A17: 6 | B17: 이유한·김현욱 (한양) | C17: 직급 | D17: ① 직급 미기재 / ② 직급 미기재 | E17: 공란 처리.
A18: 7 | B18: 양진영 (대보) | C18: 출신학교 | D18: ① "국방부" 표기 | E18: 학교 미확인 처리. 학교별 집계 제외.
A19: 8 | B19: ①-세로 시트 | C19: 구버전 기록 | D19: 신재혁 68년생·김용 69년생·태영 김학기·DL건설 박종모·대우 박재범(76) 등 가로 시트와 상이 | E19: 가로 시트(②와 일치) 기준 적용. 세로 시트 단독 인원(김학기·박종모)은 미포함.
A20: 9 | B20: ①-가로 시트 | C20: 기타 | D20: J5:K20 영역에 용도 미상 숫자(1/82, 0/81 …) 존재 | E20: 명부와 무관하여 미반영.
